2025-01-03 00:05:03,925 - exception_logger - ERROR - An exception occurred
Traceback (most recent call last):
  File "C:\Users\satwa\AppData\Local\Temp\ipykernel_7992\3259282278.py", line 12, in log_exception
    1 / 0
ZeroDivisionError: division by zero
